Workbook

Sheet Drop Down
A2: Consumption CV | B2: Post-SYN Column Wash | C2: Detritylation wash | D2: Amidite Eq | E2: Coupling Wash | F2: Oxidation | G2: Oxidation Chase + Wash | H2: Thiolation | I2: Thiolation Chase + Wash | J2: Mesylation | K2: Mesylation Chase + Wash | L2: PN1 | M2: PN1 Chase + Wash | N2: Capping | O2: Capping Chase + Wash | P2: Amine | Q2: Amine 2 min ACN chase
A3: 1.2
A4: 2.4 | B4: 12 | C4: 10 | D4: 4 | E4: 1.5 | F4: 3.57 | G4: 9 | H4: 3.34 | I4: 7 | N4: 1.12 | O4: 16 | P4: 12.5 | Q4: 8.89
A5: 3.1 | B5: 12 | C5: 8 | D5: 4 | E5: 1 | F5: 2.86 | G5: 7 | H5: 2.86 | I5: 5 | J5: 3.4 | K5: 7.6 | L5: 2.75 | M5: 7 | N5: 0.95 | O5: 13 | P5: 10 | Q5: 6.67
A6: 3.9 | B6: 12 | C6: 8 | D6: 3.5 | E6: 1 | F6: 2.24 | G6: 7 | H6: 2.45 | I6: 5 | N6: 0.79 | O6: 13 | P6: 10 | Q6: 5.33
A7: 6.3 | B7: 6 | C7: 6 | D7: 3 | E7: 0.5 | F7: 1.62 | G7: 3.5 | H7: 1.62 | I7: 2.5 | J7: 3 | K7: 4.7 | L7: 2.25 | M7: 4.5 | N7: 0.51 | O7: 5.5 | P7: 7.5 | Q7: 6.67
A8: 12 | B8: 6 | C8: 4 | D8: 2.5 | E8: 0.5 | F8: 1.33 | G8: 2.7 | H8: 1.06 | I8: 1.7 | J8: 2.4 | K8: 4.2 | N8: 0.38 | O8: 2.7 | P8: 5 | Q8: 6.35
A9: 17.2 | B9: 6 | C9: 4 | D9: 2 | E9: 0.5 | F9: 1.31 | G9: 2.7 | H9: 1.05 | I9: 1.7 | N9: 0.37 | O9: 2.7 | P9: 5 | Q9: 4.45
A10: 22.9 | B10: 6 | C10: 4 | D10: 2 | E10: 0.5 | F10: 1.31 | G10: 2.7 | H10: 1.05 | I10: 1.7 | N10: 0.37 | O10: 2.7 | P10: 5 | Q10: 3.34
A11: 28.6 | B11: 6 | C11: 4 | D11: 2 | E11: 0.5 | F11: 1.31 | G11: 2.7 | H11: 1.05 | I11: 1.7 | N11: 0.37 | O11: 2.7 | P11: 5
A12: 34.4 | B12: 4 | C12: 4 | D12: 2 | E12: 0.5 | F12: 1.31 | G12: 2.2 | H12: 1.05 | I12: 1.7 | N12: 0.37 | O12: 1.7 | P12: 5
A13: 40.1 | B13: 4 | C13: 4 | D13: 2 | E13: 0.5 | F13: 1.31 | G13: 2.2 | H13: 1.05 | I13: 1.7 | N13: 0.37 | O13: 1.7 | P13: 5
A14: 45.8 | B14: 4 | C14: 4 | D14: 2 | E14: 0.5 | F14: 1.31 | G14: 2.2 | H14: 1.05 | I14: 1.7 | N14: 0.37 | O14: 1.7 | P14: 5
A15: 51.5 | B15: 4 | C15: 4 | D15: 2 | E15: 0.5 | F15: 1.31 | G15: 2.2 | H15: 1.05 | I15: 1.7 | N15: 0.37 | O15: 1.7 | P15: 5
A16: 24 | B16: 6 | C16: 4 | D16: 2 | E16: 0.5 | F16: 1.33 | G16: 2.7 | H16: 1.06 | I16: 1.7 | N16: 0.38 | O16: 1.7 | P16: 5 | Q16: 5.33
A17: 48 | B17: 4 | C17: 4 | D17: 2 | E17: 0.5 | F17: 1.33 | G17: 2.2 | H17: 0.8 | I17: 1.7 | J17: 1.4 | K17: 2.7 | N17: 0.38 | O17: 1.7 | P17: 5 | Q17: 4.22
A18: FL35 | B18: 4 | C18: 4 | D18: 2 | E18: 0.5 | F18: 1.35 | G18: 2.2 | H18: 0.8 | I18: 1.7 | N18: 0.38 | O18: 1.7 | P18: 5 | Q18: 2.42
A19: Agar6 | B19: 4 | C19: 4 | D19: 2 | E19: 0.5 | F19: 1.35 | G19: 2.2 | H19: 0.8 | I19: 1.7 | N19: 0.38 | O19: 1.7 | P19: 5

Sheet SYN Scale
A1: Update | B1: Scale | C1: Solid Support Pore Size | D1: Solid Support Loading | E1: Solid Support Density | F1: Solid Support Weight | G1: Column I.D. | H1: BH | I1: CV | J1: Column | K1: Note
B2: umol | C2: Å | D2: umol/g | E2: g/ml | F2: g | G2: cm | H2: cm | I2: mL | J2: mL
A3: 20250414 | B3: 80 | C3: 500 | D3: 85 | E3: 0.3 | F3: =B3/D3 -> 0.94117647 | G3: 1 | H3: =I3/PI()/(G3/2)^2 -> 3.994477 | I3: =F3/E3 -> 3.1372549 | J3: 3.1
B4: 100 | C4: 500 | D4: 85 | E4: 0.3 | F4: =B4/D4 -> 1.1764706 | G4: 1 | H4: =I4/PI()/(G4/2)^2 -> 4.9930963 | I4: =F4/E4 -> 3.9215686 | J4: 3.9
A5: 20250403 | B5: 160 | C5: 500 | D5: 85 | E5: 0.3 | F5: =B5/D5 -> 1.8823529 | G5: 2 | H5: =I5/PI()/(G5/2)^2 -> 1.9972385 | I5: =F5/E5 -> 6.2745098 | J5: 6.3
A6: 20240824 | B6: 305 | C6: 500 | D6: 85 | E6: 0.3 | F6: =B6/D6 -> 3.5882353 | G6: 2.7 | H6: =I6/PI()/(G6/2)^2 -> 2.0890183 | I6: =F6/E6 -> 11.960784 | J6: 12
A7: 20240824 | B7: 440 | C7: 500 | D7: 85 | E7: 0.3 | F7: =B7/D7 -> 5.1764706 | G7: 2.7 | H7: =I7/PI()/(G7/2)^2 -> 3.0136658 | I7: =F7/E7 -> 17.254902 | J7: 17.2
A8: 20240824 | B8: 585 | C8: 500 | D8: 85 | E8: 0.3 | F8: =B8/D8 -> 6.8823529 | G8: 2.7 | H8: =I8/PI()/(G8/2)^2 -> 4.0068056 | I8: =F8/E8 -> 22.941176 | J8: 22.9
A9: 20241219 | B9: 730 | C9: 500 | D9: 85 | E9: 0.3 | F9: =B9/D9 -> 8.5882353 | G9: 2.7 | H9: =I9/PI()/(G9/2)^2 -> 4.9999455 | I9: =F9/E9 -> 28.627451 | J9: 28.6
A10: 20241206 | B10: 875 | C10: 500 | D10: 85 | E10: 0.3 | F10: =B10/D10 -> 10.294118 | G10: 2.7 | H10: =I10/PI()/(G10/2)^2 -> 5.9930854 | I10: =F10/E10 -> 34.313725 | J10: 34.4
A11: 20241223 | B11: 1020 | C11: 500 | D11: 85 | E11: 0.3 | F11: =B11/D11 -> 12 | G11: 2.7 | H11: =I11/PI()/(G11/2)^2 -> 6.9862252 | I11: =F11/E11 -> 40 | J11: 40.1
B12: 1170 | C12: 500 | D12: 85 | E12: 0.3 | F12: =B12/D12 -> 13.764706 | G12: 2.7 | H12: =I12/PI()/(G12/2)^2 -> 8.0136113 | I12: =F12/E12 -> 45.882353 | J12: 45.8
B13: 1315 | C13: 500 | D13: 85 | E13: 0.3 | F13: =B13/D13 -> 15.470588 | G13: 2.7 | H13: =I13/PI()/(G13/2)^2 -> 9.0067511 | I13: =F13/E13 -> 51.568627 | J13: 51.5
A14: 20240824 | B14: 615 | C14: 500 | D14: 85 | E14: 0.3 | F14: =B14/D14 -> 7.2352941 | G14: 3.5 | H14: =I14/PI()/(G14/2)^2 -> 2.5067381 | I14: =F14/E14 -> 24.117647 | J14: 24
A15: 20240824 | B15: 1225 | C15: 500 | D15: 85 | E15: 0.3 | F15: =B15/D15 -> 14.411765 | G15: 4.4 | H15: =I15/PI()/(G15/2)^2 -> 3.1593713 | I15: =F15/E15 -> 48.039216 | J15: 48
B16: 1400 | C16: 500 | D16: 85 | E16: 0.3 | F16: =B16/D16 -> 16.470588 | G16: 3.5 | H16: =I16/PI()/(G16/2)^2 -> 5.7063957 | I16: =F16/E16 -> 54.901961 | J16: FL35
A17: 20241219 | B17: 1500 | C17: 500 | D17: 85 | E17: 0.3 | F17: =B17/D17 -> 17.647059 | G17: 3.5 | H17: =I17/PI()/(G17/2)^2 -> 6.1139954 | I17: =F17/E17 -> 58.823529 | J17: FL35
B18: 1600 | C18: 500 | D18: 85 | E18: 0.3 | F18: =B18/D18 -> 18.823529 | G18: 3.5 | H18: =I18/PI()/(G18/2)^2 -> 6.5215951 | I18: =F18/E18 -> 62.745098 | J18: FL35
B19: 1800 | C19: 500 | D19: 85 | E19: 0.3 | F19: =B19/D19 -> 21.176471 | G19: 3.5 | H19: =I19/PI()/(G19/2)^2 -> 7.3367945 | I19: =F19/E19 -> 70.588235 | J19: FL35
B20: 2000 | C20: 500 | D20: 85 | E20: 0.3 | F20: =B20/D20 -> 23.529412 | G20: 3.5 | H20: =I20/PI()/(G20/2)^2 -> 8.1519939 | I20: =F20/E20 -> 78.431373 | J20: FL35
B21: 2200 | C21: 500 | D21: 85 | E21: 0.3 | F21: =B21/D21 -> 25.882353 | G21: 3.5 | H21: =I21/PI()/(G21/2)^2 -> 8.9671933 | I21: =F21/E21 -> 86.27451 | J21: FL35
B22: 2400 | C22: 500 | D22: 85 | E22: 0.3 | F22: =B22/D22 -> 28.235294 | G22: 3.5 | H22: =I22/PI()/(G22/2)^2 -> 9.7823927 | I22: =F22/E22 -> 94.117647 | J22: FL35
B23: 2450 | C23: 500 | D23: 85 | E23: 0.3 | F23: =B23/D23 -> 28.823529 | G23: 3.5 | H23: =I23/PI()/(G23/2)^2 -> 9.9861925 | I23: =F23/E23 -> 96.078431 | J23: FL35
B24: 7210 | C24: 500 | D24: 85 | E24: 0.3 | F24: =B24/D24 -> 84.823529 | G24: 6 | H24: =I24/PI()/(G24/2)^2 -> 10.000062 | I24: =F24/E24 -> 282.7451 | J24: Agar6
A25: 20241207 | B25: 45 | C25: 1000 | D25: 45 | E25: 0.29 | F25: =B25/D25 -> 1 | G25: 1 | H25: =I25/PI()/(G25/2)^2 -> 4.3904812 | I25: =F25/E25 -> 3.4482759 | J25: 3.1
A26: 20240824 | B26: 55 | C26: 1000 | D26: 45 | E26: 0.29 | F26: =B26/D26 -> 1.2222222 | G26: 1 | H26: =I26/PI()/(G26/2)^2 -> 5.3661437 | I26: =F26/E26 -> 4.2145594 | J26: 3.9
A27: 20240824 | B27: 85 | C27: 1000 | D27: 45 | E27: 0.29 | F27: =B27/D27 -> 1.8888889 | G27: 2 | H27: =I27/PI()/(G27/2)^2 -> 2.0732828 | I27: =F27/E27 -> 6.51341 | J27: 6.3
A28: 20240824 | B28: 160 | C28: 1000 | D28: 45 | E28: 0.29 | F28: =B28/D28 -> 3.5555556 | G28: 2.7 | H28: =I28/PI()/(G28/2)^2 -> 2.1413717 | I28: =F28/E28 -> 12.260536 | J28: 12
A29: 20240824 | B29: 225 | C29: 1000 | D29: 45 | E29: 0.29 | F29: =B29/D29 -> 5 | G29: 2.7 | H29: =I29/PI()/(G29/2)^2 -> 3.011304 | I29: =F29/E29 -> 17.241379 | J29: 17.2
A30: 20250815 | B30: 300 | C30: 1000 | D30: 45 | E30: 0.29 | F30: =B30/D30 -> 6.6666667 | G30: 2.7 | H30: =I30/PI()/(G30/2)^2 -> 4.015072 | I30: =F30/E30 -> 22.988506 | J30: 22.9
B31: 375 | C31: 1000 | D31: 45 | E31: 0.29 | F31: =B31/D31 -> 8.3333333 | G31: 2.7 | H31: =I31/PI()/(G31/2)^2 -> 5.01884 | I31: =F31/E31 -> 28.735632 | J31: 28.6
A32: 2024 | B32: 450 | C32: 1000 | D32: 45 | E32: 0.29 | F32: =B32/D32 -> 10 | G32: 2.7 | H32: =I32/PI()/(G32/2)^2 -> 6.0226079 | I32: =F32/E32 -> 34.482759 | J32: 34.4
B33: 525 | C33: 1000 | D33: 45 | E33: 0.29 | F33: =B33/D33 -> 11.666667 | G33: 2.7 | H33: =I33/PI()/(G33/2)^2 -> 7.0263759 | I33: =F33/E33 -> 40.229885 | J33: 40.1
B34: 600 | C34: 1000 | D34: 45 | E34: 0.29 | F34: =B34/D34 -> 13.333333 | G34: 2.7 | H34: =I34/PI()/(G34/2)^2 -> 8.0301439 | I34: =F34/E34 -> 45.977011 | J34: 45.8
B35: 675 | C35: 1000 | D35: 45 | E35: 0.29 | F35: =B35/D35 -> 15 | G35: 2.7 | H35: =I35/PI()/(G35/2)^2 -> 9.0339119 | I35: =F35/E35 -> 51.724138 | J35: 51.5
A36: 20240824 | B36: 320 | C36: 1000 | D36: 45 | E36: 0.29 | F36: =B36/D36 -> 7.1111111 | G36: 3.5 | H36: =I36/PI()/(G36/2)^2 -> 2.5486694 | I36: =F36/E36 -> 24.521073 | J36: 24
A37: 20240824 | B37: 640 | C37: 1000 | D37: 45 | E37: 0.29 | F37: =B37/D37 -> 14.222222 | G37: 4.4 | H37: =I37/PI()/(G37/2)^2 -> 3.2253305 | I37: =F37/E37 -> 49.042146 | J37: 48
A38: 20240824 | B38: 1000 | C38: 1000 | D38: 45 | E38: 0.29 | F38: =B38/D38 -> 22.222222 | G38: 3.5 | H38: =I38/PI()/(G38/2)^2 -> 7.9645917 | I38: =F38/E38 -> 76.628352 | J38: FL35
B39: 1255 | C39: 1000 | D39: 45 | E39: 0.29 | F39: =B39/D39 -> 27.888889 | G39: 3.5 | H39: =I39/PI()/(G39/2)^2 -> 9.9955626 | I39: =F39/E39 -> 96.168582 | J39: FL35
B40: 3690 | C40: 1000 | D40: 45 | E40: 0.29 | F40: =B40/D40 -> 82 | G40: 6 | H40: =I40/PI()/(G40/2)^2 -> 10.00054 | I40: =F40/E40 -> 282.75862 | J40: Agar6
...

Sheet Consumption
A2: Reagent Consumption and Waste Calculator (Base Eq) | F2: Reagent Vol Calculator
A3: Setting | B3: Scale | C3: 45 | D3: umol | F3: Setting | G3: Scale | H3: 510 | I3: umol
B4: CV | C4: 3.1 | D4: mL | G4: CV | H4: 34.4 | I4: mL
B5: Cycle | C5: 19 | G5: Cycle | H5: 24
B6: Final Detritylation | C6: 1 | D6: 1 or 0 | G6: Final Detritylation | H6: 1 | I6: 1 or 0
A8: ACN | B8: Pre-SYN Column Wash (leakage check) | C8: 5 | D8: CV | F8: ACN | G8: Pre-SYN Column Wash (leakage check) | H8: 5 | I8: CV
B9: Auto Zero Wash | C9: 25 | D9: mL | G9: Auto Zero Wash | H9: 25 | I9: mL
B10: System Wash | C10: 40 | D10: mL | G10: System Wash | H10: 40 | I10: mL
B11: Amidite/Reagent Purge Wash (ave. 8+6) | C11: 140 | D11: mL | G11: Amidite/Reagent Purge Wash (ave. 8+6) | H11: 140 | I11: mL
B12: Post-SYN Column Wash (4 - 6 CV) | C12: 12 | D12: CV | G12: Post-SYN Column Wash (4 - 6 CV) | H12: =IFERROR(_xlfn.XLOOKUP(H4,'Drop Down'!A3:A53,'Drop Down'!B3:B53),"") -> 4 | I12: CV
A14: Detritylation | B14: Auto Zero | C14: 50 | D14: mL | F14: Detritylation | G14: Auto Zero | H14: 50 | I14: mL
B15: Ave. Detritylation (4.2 CV) | C15: 4.5 | D15: CV | G15: Ave. Detritylation (4.2 CV) | H15: 4.5 | I15: CV
B16: Detritylation wash (4 - 8 CV) | C16: 8 | D16: CV | G16: Detritylation wash (4 - 8 CV) | H16: =IFERROR(_xlfn.XLOOKUP(H4,'Drop Down'!A3:A53,'Drop Down'!C3:C53),"") -> 4 | I16: CV
A18: Coupling | B18: Coupling Port Wash + Chase (each cycle) | C18: 16 | D18: mL | F18: Coupling | G18: Coupling Port Wash + Chase (each cycle) | H18: 16 | I18: mL
B19: Amidite Eq (2.0 - 4.0) | C19: 4 | D19: eq | G19: Amidite Eq (2.0 - 4.0) | H19: =IFERROR(_xlfn.XLOOKUP(H4,'Drop Down'!A3:A53,'Drop Down'!D3:D53),"") -> 2 | I19: eq
B20: Amidite Conc | C20: 0.12 | D20: M | G20: Amidite Conc | H20: 0.12 | I20: M
B21: Act %vol | C21: 0.6 | G21: Act %vol | H21: 0.6
B22: Coupling Wash (0.5 -1.0 CV) | C22: 1 | D22: CV | G22: Coupling Wash (0.5 -1.0 CV) | H22: =IFERROR(_xlfn.XLOOKUP(H4,'Drop Down'!A3:A53,'Drop Down'!E3:E53),"") -> 0.5 | I22: CV
A24: Oxidation | B24: Oxidation Eq (2.5 - 10.0) | C24: 10 | D24: eq | F24: Oxidation | G24: Oxidation Eq (2.5 - 10.0) | H24: NA | I24: eq
B25: Oxidation Conc | C25: 0.05 | D25: M | G25: Oxidation Conc | H25: 0.05 | I25: M
B26: Oxidation | C26: =C3/1000*C24/C25/C4 -> 2.9032258 | D26: CV | G26: Oxidation | H26: =IFERROR(_xlfn.XLOOKUP(H4,'Drop Down'!A3:A53,'Drop Down'!F3:F53),"") -> 1.31 | I26: CV
B27: Oxidation Chase + Wash (2.2 - 7.0 CV) | C27: 7 | D27: CV | G27: Oxidation Chase + Wash (2.2 - 7.0 CV) | H27: =IFERROR(_xlfn.XLOOKUP(H4,'Drop Down'!A3:A53,'Drop Down'!G3:G53),"") -> 2.2 | I27: CV
A29: Thiolation | B29: ps | C29: 0 | F29: Thiolation | G29: ps | H29: 4
B30: Thiolation Eq (6.0 - 40.0) | C30: 40 | D30: eq | G30: Thiolation Eq (6.0 - 40.0) | H30: NA | I30: eq
B31: Thiolation Conc | C31: 0.2 | D31: M | G31: Thiolation Conc | H31: 0.2 | I31: M
B32: Thiolation | C32: =C3/1000*C30/C31/C4 -> 2.9032258 | D32: CV | G32: Thiolation | H32: =IFERROR(_xlfn.XLOOKUP(H4,'Drop Down'!A3:A53,'Drop Down'!H3:H53),"") -> 1.05 | I32: CV
B33: Thiolation Chase + Wash (1.7 - 5.0 CV) | C33: 5 | D33: CV | G33: Thiolation Chase + Wash (1.7 - 5.0 CV) | H33: =IFERROR(_xlfn.XLOOKUP(H4,'Drop Down'!A3:A53,'Drop Down'!I3:I53),"") -> 1.7 | I33: CV
A35: Mesylation | B35: mspa | C35: 2 | F35: Mesylation | G35: mesyl | H35: 0
B36: MsN3 Eq (? - 117.1) | C36: 117.1 | D36: eq | G36: MsN3 Eq (? - 117.1) | H36: NA | I36: eq
B37: MsN3 Conc | C37: 0.5 | D37: M | G37: MsN3 Conc | H37: 0.5 | I37: M
B38: Mesylation | C38: =C3/1000*C36/C37/C4 -> 3.3996774 | D38: CV | G38: Mesylation | H38: =IFERROR(_xlfn.XLOOKUP(H4,'Drop Down'!A3:A53,'Drop Down'!J3:J53),"") -> 0 | I38: CV
B39: Mesylation Chase + Wash (2.7 - 7.6 CV) | C39: 7.6 | D39: CV | G39: Mesylation Chase + Wash (2.7 - 7.6 CV) | H39: =IFERROR(_xlfn.XLOOKUP(H4,'Drop Down'!A3:A53,'Drop Down'!K3:K53),"") -> 0 | I39: CV
A41: PN1 | B41: pn1 | C41: 1 | F41: PN1 | G41: pn1 | H41: 0
B42: ADMP Eq (? - 37.9) | C42: 37.9 | D42: eq | G42: ADMP Eq (? - 37.9) | H42: NA | I42: eq
B43: ADMP Conc | C43: 0.2 | D43: M | G43: ADMP Conc | H43: 0.2 | I43: M
B44: PN1 | C44: =C3/1000*C42/C43/C4 -> 2.7508065 | D44: CV | G44: PN1 | H44: =IFERROR(_xlfn.XLOOKUP(H4,'Drop Down'!A3:A53,'Drop Down'!L3:L53),"") -> 0 | I44: CV
B45: PN1 Chase + Wash (? - 7.6 CV) | C45: 7 | D45: CV | G45: PN1 Chase + Wash (? - 7.6 CV) | H45: =IFERROR(_xlfn.XLOOKUP(H4,'Drop Down'!A3:A53,'Drop Down'!M3:M53),"") -> 0 | I45: CV
A47: Capping | B47: Capping Eq (15.0 - 70.0) | C47: 70 | D47: eq | F47: Capping | G47: Capping Eq (15.0 - 70.0) | H47: NA | I47: eq
B48: Capping Conc | C48: 1.058 | D48: M | G48: Capping Conc | H48: 1.058 | I48: M
B49: Capping | C49: =C3/1000*C47/C48/C4 -> 0.96042442 | D49: CV | G49: Capping | H49: =IFERROR(_xlfn.XLOOKUP(H4,'Drop Down'!A3:A53,'Drop Down'!N3:N53),"") -> 0.37 | I49: CV
...

Sheet 4mmol, 6.69mmol
A1: S21392 | B1: 4.0 mmol
B2: ACN | C2: 17.08358 | D2: L
B3: 3%DCA in DCM | C3: 10.04702 | D3: L
B4: 0.2 M Amidite per cycle | C4: 40 | D4: mL
B5: 0.6 M ACT | C5: 1.4852941 | D5: L
B6: Ox | C6: 0.21 | D6: L
B7: 0.2 M XH | C7: 2.05 | D7: L
B8: 0.5 M MsN3/BsN3 | C8: 0 | D8: L
B9: 0.2 M ADMP | C9: 0 | D9: L
B10: CapA | C10: 0.34526465 | D10: L
B11: CapB | C11: 0.34526465 | D11: L
B12: Amine | C12: 0.5545 | D12: L
B13: Total Waste | C13: 32.880923 | D13: L
A15: S21393 | B15: 6.69 mmol
B16: ACN | C16: 25.2378 | D16: L
B17: 3%DCA in DCM | C17: 14.8196 | D17: L
B18: 0.2 M Amidite per cycle | C18: 66.9 | D18: mL
B19: 0.6 M ACT | C19: 2.2177 | D19: L
B20: Ox | C20: 0.3445 | D20: L
B21: 0.2 M XH | C21: 3.0205 | D21: L
B22: 0.5 M MsN3/BsN3 | C22: 0 | D22: L
B23: 0.2 M ADMP | C23: 0 | D23: L
B24: CapA | C24: 0.51086011 | D24: L
B25: CapB | C25: 0.51086011 | D25: L
B26: Amine | C26: 0.915 | D26: L
B27: Total Waste | C27: 48.71412 | D27: L
